Workbook

Sheet OLD
M1: =SUBTOTAL(9,M3:M1048576) -> 9 | N1: =SUBTOTAL(9,N3:N1048576) -> 381411.3 | O1: =SUBTOTAL(9,O3:O1048576) -> 0 | P1: =SUBTOTAL(9,P3:P1048576) -> 381411.3
A2: No | B2: Status | C2: Completion_status | D2: Project type | E2: Customer code | F2: Customer Name | G2: Project Name | H2: PIC | I2: PIC OLD | J2: Market | K2: Stage | L2: Prototype requested | M2: Total SKU | N2: Project total amount (USD) | O2: Shipped amount (USD) | P2: Outstanding amount (USD) | Q2: Payment term | R2: PRE-PAYMENT RECEIVED | S2: BOQ date | T2: PO received | U2: PO date | V2: Prototype requested SD | W2: Prototype confirmed SW | X2: Prototype confirmed SD | Y2: Prototype confirmed SM | Z2: Production requested SD | AA2: Production requested SM | AB2: Production confirmed SW | AC2: Production confirmed SD | AD2: Production confirmed SM | AE2: Shipping information | AF2: Drawing status | AG2: Veneer /wood | AH2: Marble | AI2: Metal | AJ2: Mirror | AK2: Electrical part | AL2: Fabric | AM2: Remark | AN2: Notes | AO2: Forecase Value | AP2: Forecast SM | AQ2: Customer required SW | AR2: SAMPLE SHIPPED DATE
A3: =ROW(A3)-ROW($A$2) -> 1 | B3: Green | C3: IN PROGRESS | D3: NON RH | E3: RFF-CO | F3: COSMIC REALTY PARTNERS LLC | G3: 250 FIFTH AVENUE HOTEL | H3: THƯ | I3: THƯ | J3: US | K3: PRODUCTION | M3: 17 | N3: 54476.23 | O3: 52267.43 | P3: =N3-O3 -> 2208.8 | R3: YES | S3: 45968 | X3: =VLOOKUP(W3,'2026 Calendar'!A:E,4,0) -> #N/A | Y3: =VLOOKUP(W3,'2026 Calendar'!A:B,2,0) -> #N/A | Z3: 46116 | AA3: April | AB3: W14 | AC3: =VLOOKUP(AB3,'2026 Calendar'!A:E,4,0) -> #N/A | AD3: =VLOOKUP(AB3,'2026 Calendar'!A:B,2,0) -> #N/A | AF3: Approved | AG3: Approved | AH3: Approved | AI3: Approved | AJ3: Approved | AK3: Approved | AL3: COM | AM3: Reorder | AQ3: 46062
A4: =ROW(A4)-ROW($A$2) -> 2 | B4: Green | C4: IN PROGRESS | D4: RH | E4: RFF-RH/HS | F4: RESTORATION HARDWARE_HS | G4: BOUTIQUE HOTEL | H4: DŨNG | I4: DŨNG | J4: US | K4: PRODUCTION | L4: NO | M4: 9 | N4: 54061.6 | P4: =N4-O4 -> 54061.6 | Q4: NO REQUIRE | S4: 45955 | T4: YES | U4: 45964 | Y4: =VLOOKUP(W4,'2026 Calendar'!A:B,2,0) -> #N/A | AB4: W15 | AC4: =VLOOKUP(AB4,'2026 Calendar'!A:E,4,0) -> #N/A | AD4: =VLOOKUP(AB4,'2026 Calendar'!A:B,2,0) -> #N/A | AF4: Approved | AG4: Approved | AH4: None | AI4: Approved | AJ4: None | AK4: RSC purchase | AL4: COM | AM4: COM received. Pending MCP for metal (black color) | AN4: COM received. Pending MCP for metal (black color) | AQ4: 46174 | AR4: 46174
A5: =ROW(A5)-ROW($A$2) -> 3 | C5: IN PROGRESS | D5: RH | E5: RFF-RH/HS | F5: RESTORATION HARDWARE_HS | G5: CHICAGO PENDRY | H5: DŨNG | I5: SƯƠNG | J5: US | K5: PRODUCTION | L5: NO | M5: 2 | N5: 135705 | P5: =N5-O5 -> 135705 | S5: 45856 | T5: NO | X5: =VLOOKUP(W5,'2026 Calendar'!A:E,4,0) -> #N/A | Y5: =VLOOKUP(W5,'2026 Calendar'!A:B,2,0) -> #N/A | AC5: =VLOOKUP(AB5,'2026 Calendar'!A:E,4,0) -> #N/A | AD5: =VLOOKUP(AB5,'2026 Calendar'!A:B,2,0) -> #N/A | AF5: Pending approval | AG5: Pending approval | AH5: Pending approval | AI5: Pending approval | AJ5: None | AK5: None | AL5: None | AQ5: N/A
A6: =ROW(A6)-ROW($A$2) -> 4 | C6: IN PROGRESS | D6: RH | E6: RFF-RH/HS | F6: RESTORATION HARDWARE_HS | G6: CIA O&O GUESTROOMS | H6: DŨNG | I6: DŨNG | J6: US | K6: PRODUCTION | M6: 14 | N6: 100196.28 | P6: =N6-O6 -> 100196.28 | Q6: NO REQUIRE | S6: N/A | T6: NO | X6: =VLOOKUP(W6,'2026 Calendar'!A:E,4,0) -> #N/A | Y6: =VLOOKUP(W6,'2026 Calendar'!A:B,2,0) -> #N/A | AC6: =VLOOKUP(AB6,'2026 Calendar'!A:E,4,0) -> #N/A | AD6: =VLOOKUP(AB6,'2026 Calendar'!A:B,2,0) -> #N/A | AQ6: N/A
A7: =ROW(A7)-ROW($A$2) -> 5 | B7: Yellow | C7: IN PROGRESS | D7: RH | E7: RFF-RH/HS | F7: RESTORATION HARDWARE_HS | G7: CIA O&O GUESTROOMS | H7: DŨNG | I7: DŨNG | J7: US | K7: SAMPLE ROOM | L7: YES | M7: 14 | N7: 10991.34 | P7: =N7-O7 -> 10991.34 | Q7: NO REQUIRE | S7: 45981 | T7: YES | U7: 45992 | X7: 46157 | Y7: =VLOOKUP(W7,'2026 Calendar'!A:B,2,0) -> #N/A | AC7: =VLOOKUP(AB7,'2026 Calendar'!A:E,4,0) -> #N/A | AD7: =VLOOKUP(AB7,'2026 Calendar'!A:B,2,0) -> #N/A | AF7: WIP revision | AG7: Pending approval | AH7: Pending approval | AI7: Pending approval | AJ7: Use available | AK7: None | AL7: COM | AM7: Marble: Graphite WIP sourcing | AQ7: 46112 | AR7: 46112
A8: =ROW(A8)-ROW($A$2) -> 6 | B8: Grey | C8: IN PROGRESS | D8: NON RH | E8: RFF-TMSJ | F8: LANG & SCHWANDER LLC | G8: DELAMAR MYSTIC | H8: THƯ | I8: THƯ | J8: US | K8: PRODUCTION FOC | M8: 1 | N8: 16800 | P8: =N8-O8 -> 16800 | Q8: NO REQUIRE | X8: =VLOOKUP(W8,'2026 Calendar'!A:E,4,0) -> #N/A | Y8: =VLOOKUP(W8,'2026 Calendar'!A:B,2,0) -> #N/A | Z8: 46101 | AA8: March | AB8: W12 | AC8: =VLOOKUP(AB8,'2026 Calendar'!A:E,4,0) -> #N/A | AD8: =VLOOKUP(AB8,'2026 Calendar'!A:B,2,0) -> #N/A | AF8: Approved | AG8: Approved | AH8: Approved | AI8: Approved | AJ8: Approved | AK8: Approved | AL8: RSC purchase | AM8: FOC replacements, pending approval of used leather from customer | AQ8: Pending
A9: =ROW(A9)-ROW($A$2) -> 7 | B9: Red | C9: IN PROGRESS | D9: NON RH | E9: RFF-TMSJ | F9: LANG & SCHWANDER LLC | G9: ELYSEE HOTEL | H9: THƯ | I9: SƯƠNG | J9: US | K9: PRODUCTION | M9: 35 | N9: 232948 | P9: =N9-O9 -> 232948 | R9: YES | S9: 46009 | T9: YES | U9: 46009 | X9: =VLOOKUP(W9,'2026 Calendar'!A:E,4,0) -> #N/A | Y9: =VLOOKUP(W9,'2026 Calendar'!A:B,2,0) -> #N/A | Z9: 46188 | AA9: June | AB9: NA | AC9: =VLOOKUP(AB9,'2026 Calendar'!A:E,4,0) -> #N/A | AD9: =VLOOKUP(AB9,'2026 Calendar'!A:B,2,0) -> #N/A | AF9: Pending approval | AG9: Pending approval | AH9: Pending approval | AI9: Pending approval | AJ9: Pending approval | AK9: None | AL9: COM | AM9: pending submission drawing from ME, waiting client to approve color and bed drawing | AQ9: 46128
A10: =ROW(A10)-ROW($A$2) -> 8 | B10: Red | C10: IN PROGRESS | D10: NON RH | E10: RFF-TMSJ | F10: LANG & SCHWANDER LLC | G10: ELYSEE HOTEL | H10: THƯ | I10: SƯƠNG | J10: US | K10: SAMPLE ROOM | M10: 5 | N10: 1936.89 | P10: =N10-O10 -> 1936.89 | R10: YES | S10: 46009 | T10: YES | U10: 46009 | V10: 46122 | X10: =VLOOKUP(W10,'2026 Calendar'!A:E,4,0) -> #N/A | Y10: =VLOOKUP(W10,'2026 Calendar'!A:B,2,0) -> #N/A | AC10: =VLOOKUP(AB10,'2026 Calendar'!A:E,4,0) -> #N/A | AD10: =VLOOKUP(AB10,'2026 Calendar'!A:B,2,0) -> #N/A | AF10: Pending approval | AG10: Pending approval | AH10: Pending approval | AI10: Pending approval | AJ10: Pending approval | AK10: None | AL10: COM | AM10: pending submission drawing from ME, waiting client to approve color and bed drawing | AQ10: 46128
A11: =ROW(A11)-ROW($A$2) -> 9 | C11: IN PROGRESS | D11: NON RH | E11: RFF-TMSJ | F11: LANG & SCHWANDER LLC | G11: FAENA TULLUM (FTMX) | H11: TÚ ANH | I11: TÚ ANH | J11: MX | K11: PRODUCTION | L11: YES | M11: 12 | N11: 949496.23 | P11: =N11-O11 -> 949496.23 | S11: 45798 | T11: NO | X11: =VLOOKUP(W11,'2026 Calendar'!A:E,4,0) -> #N/A | Y11: =VLOOKUP(W11,'2026 Calendar'!A:B,2,0) -> #N/A | AC11: =VLOOKUP(AB11,'2026 Calendar'!A:E,4,0) -> #N/A | AD11: =VLOOKUP(AB11,'2026 Calendar'!A:B,2,0) -> #N/A | AQ11: N/A
A12: =ROW(A12)-ROW($A$2) -> 10 | B12: Red | C12: IN PROGRESS | D12: NON RH | E12: RFF-FLF | F12: FLEETWOOD FURNITURE | G12: FOUR SEASON JACKSONVILLE | H12: TÚ ANH | I12: TÚ ANH | J12: US | K12: PRODUCTION | L12: YES | M12: 37 | N12: 197691.81 | P12: =N12-O12 -> 197691.81 | R12: YES | S12: 45986 | T12: YES | U12: 46053 | X12: =VLOOKUP(W12,'2026 Calendar'!A:E,4,0) -> #N/A | Y12: =VLOOKUP(W12,'2026 Calendar'!A:B,2,0) -> #N/A | Z12: 46121 | AA12: April | AB12: W16 | AC12: 46128 | AD12: April | AE12: Airship and Sea | AF12: Approved | AG12: Approved | AH12: None | AI12: Approved | AJ12: None | AK12: Approved | AL12: None | AN12: Ask customer if have QC inspection. Client request production status update including images | AQ12: 46112 | AR12: 45744
A13: =ROW(A13)-ROW($A$2) -> 11 | B13: Green | C13: IN PROGRESS | D13: RH | E13: RFF-RH/HS | F13: RESTORATION HARDWARE_HS | G13: FOX HARBOR | H13: TUYẾT | I13: TUYẾT | J13: US | K13: PRODUCTION | M13: 12 | N13: 66302.16 | O13: 35918.61 | P13: =N13-O13 -> 30383.55 | Q13: NO REQUIRE | S13: 46000 | X13: =VLOOKUP(W13,'2026 Calendar'!A:E,4,0) -> #N/A | Y13: =VLOOKUP(W13,'2026 Calendar'!A:B,2,0) -> #N/A | AC13: =VLOOKUP(AB13,'2026 Calendar'!A:E,4,0) -> #N/A | AD13: =VLOOKUP(AB13,'2026 Calendar'!A:B,2,0) -> #N/A | AF13: Approved | AG13: Approved | AH13: Approved | AI13: Approved | AJ13: Approved | AK13: Approved | AL13: COM | AM13: COM: 3/3 received, Phase 3 | AQ13: 46116
A14: =ROW(A14)-ROW($A$2) -> 12 | B14: Red | C14: IN PROGRESS | D14: RH | E14: RFF-RH/HS | F14: RESTORATION HARDWARE_HS | G14: GRAND HYATT BAHA MAR | H14: TUYẾT | I14: TUYẾT | J14: US | K14: PRODUCTION | L14: YES | M14: 26 | N14: 2416687.2 | P14: =N14-O14 -> 2416687.2 | Q14: NO REQUIRE | S14: 46011 | T14: YES | X14: =VLOOKUP(W14,'2026 Calendar'!A:E,4,0) -> #N/A | Y14: =VLOOKUP(W14,'2026 Calendar'!A:B,2,0) -> #N/A | AC14: =VLOOKUP(AB14,'2026 Calendar'!A:E,4,0) -> #N/A | AD14: =VLOOKUP(AB14,'2026 Calendar'!A:B,2,0) -> #N/A | AF14: Pending approval | AG14: Approved | AH14: Pending approval | AI14: Approved | AJ14: Approved | AK14: Approved | AL14: COM | AQ14: 46028
A15: =ROW(A15)-ROW($A$2) -> 13 | B15: Red | C15: IN PROGRESS | D15: RH | E15: RFF-RH/HS | F15: RESTORATION HARDWARE_HS | G15: HA Studio Pico/Wilkins | H15: TÚ ANH | I15: TÚ ANH | J15: US | K15: PRODUCTION | L15: NO | M15: 1 | N15: 10770.2 | P15: =N15-O15 -> 10770.2 | Q15: NO REQUIRE | S15: 46037 | T15: YES | U15: 46048 | X15: =VLOOKUP(W15,'2026 Calendar'!A:E,4,0) -> #N/A | Y15: =VLOOKUP(W15,'2026 Calendar'!A:B,2,0) -> #N/A | Z15: 46171 | AA15: May | AB15: W27 | AC15: 46207 | AD15: May | AE15: Sea | AF15: Approved | AG15: Pending approval | AH15: None | AI15: Approved | AJ15: None | AK15: None | AL15: None | AQ15: 46171
A16: =ROW(A16)-ROW($A$2) -> 14 | C16: IN PROGRESS | D16: NON RH | E16: RFF-FLF | F16: FLEETWOOD FURNITURE | G16: HARD ROCK LAS VEGAS WEST TOWER | H16: THẢO | I16: SƯƠNG | J16: US | K16: PRODUCTION | L16: YES | M16: 130 | N16: 4410979.8 | P16: =N16-O16 -> 4410979.8 | S16: 45891 | T16: NO | X16: =VLOOKUP(W16,'2026 Calendar'!A:E,4,0) -> #N/A | Y16: =VLOOKUP(W16,'2026 Calendar'!A:B,2,0) -> #N/A | AC16: =VLOOKUP(AB16,'2026 Calendar'!A:E,4,0) -> #N/A | AD16: =VLOOKUP(AB16,'2026 Calendar'!A:B,2,0) -> #N/A | AF16: RSC WIP | AG16: Approved | AH16: WIP soucing | AI16: Pending approval | AJ16: Pending approval | AK16: COM | AL16: COM | AM16: Metal: pending final confirmation to do PVD/baking. Mirror: pending final color for production, shipped swatches to customer. Still pending one kind of marble. | AQ16: N/A | AR16: 45996
A17: =ROW(A17)-ROW($A$2) -> 15 | B17: Green | C17: IN PROGRESS | D17: NON RH | E17: RFF-FLF | F17: FLEETWOOD FURNITURE | G17: HWVP PHASE 2 | H17: DŨNG | I17: DŨNG | J17: US | K17: PRODUCTION | L17: NO | M17: 5 | N17: 7415 | P17: =N17-O17 -> 7415 | R17: YES | S17: 45327 | T17: YES | U17: 46024 | X17: =VLOOKUP(W17,'2026 Calendar'!A:E,4,0) -> #N/A | Y17: =VLOOKUP(W17,'2026 Calendar'!A:B,2,0) -> #N/A | AC17: =VLOOKUP(AB17,'2026 Calendar'!A:E,4,0) -> #N/A | AD17: April | AF17: Approved | AG17: Approved | AH17: None | AI17: Approved | AJ17: None | AK17: RSC purchase | AL17: COM | AM17: Reorder | AQ17: 46123 | AR17: 46123
A18: =ROW(A18)-ROW($A$2) -> 16 | B18: Green | C18: IN PROGRESS | D18: NON RH | E18: RFF-TPC | F18: THE PARKER COMPANY | G18: JAMES NY NOMAD | H18: THƯ | I18: THƯ | J18: US | K18: PRODUCTION | M18: 1 | N18: 3167.51 | P18: 3167.51 | R18: NO | T18: YES | U18: 46031 | X18: =VLOOKUP(W18,'2026 Calendar'!A:E,4,0) -> #N/A | Y18: =VLOOKUP(W18,'2026 Calendar'!A:B,2,0) -> #N/A | Z18: 46116 | AA18: April | AB18: W14 | AC18: =VLOOKUP(AB18,'2026 Calendar'!A:E,4,0) -> #N/A | AD18: =VLOOKUP(AB18,'2026 Calendar'!A:B,2,0) -> #N/A | AF18: Approved | AG18: Approved | AH18: None | AI18: Approved | AJ18: None | AK18: Approved | AL18: COM | AM18: Reorder | AQ18: 46116
A19: =ROW(A19)-ROW($A$2) -> 17 | B19: Yellow | C19: IN PROGRESS | D19: NON RH | E19: RFF-KD | F19: KD TRAVIS BLOCK HOLDCO, LLC | G19: KNOX DALLAS | H19: TÚ ANH | I19: TÚ ANH | J19: US | K19: PRODUCTION | L19: YES | M19: 30 | N19: =892983.35 -> 892983.35 | O19: =756408.44+33400 -> 789808.44 | P19: =N19-O19 -> 103174.91 | R19: YES | S19: 45762 | T19: YES | U19: 46113 | X19: =VLOOKUP(W19,'2026 Calendar'!A:E,4,0) -> #N/A | Y19: =VLOOKUP(W19,'2026 Calendar'!A:B,2,0) -> #N/A | Z19: 45891 | AA19: August | AB19: W31/2025 | AC19: 45872 | AD19: August | AE19: Sea | AF19: Approved | AG19: Approved | AH19: Approved | AI19: Approved | AJ19: Approved | AK19: Approved | AL19: COM | AM19: Pending COM for specialty suite closet and addtional COM for HB | AQ19: 45993
A20: 35 | B20: Red | C20: IN PROGRESS | D20: NON RH | E20: RFF-KD | F20: KD TRAVIS BLOCK HOLDCO, LLC | G20: KNOX DALLAS SUITE | H20: TÚ ANH | I20: TÚ ANH | J20: US | K20: PRODUCTION | L20: YES | M20: 50 | N20: 369199.72 | P20: =N20-O20 -> 369199.72 | R20: YES | T20: YES | U20: 46053 | X20: =VLOOKUP(W20,'2026 Calendar'!A:E,4,0) -> #N/A | Y20: =VLOOKUP(W20,'2026 Calendar'!A:B,2,0) -> #N/A | Z20: 46157 | AA20: May | AC20: =VLOOKUP(AB20,'2026 Calendar'!A:E,4,0) -> #N/A | AD20: =VLOOKUP(AB20,'2026 Calendar'!A:B,2,0) -> #N/A | AE20: Sea | AF20: Pending approval | AG20: Pending approval | AH20: Approved | AI20: Approved | AJ20: Approved | AK20: RSC purchase | AL20: COM | AN20: NPI proposed SW28/29/30 (Jul) Deposit Must be received by 18 March Fabric COM (Leather) Must be received by 13 April Veneer – Tabu: estimates the air cost to be at ~950 | AQ20: 46157
A21: =ROW(A21)-ROW($A$2) -> 19 | C21: IN PROGRESS | D21: NON RH | E21: RFF-AHMA | F21: AHMADIAH CONTRACTING & TRADING CO.-BRANCH KSA | G21: MARRIOTT KHOBAR | H21: THƯ | I21: THƯ | J21: SA | K21: PRODUCTION | L21: YES | M21: 35 | N21: 1998983 | P21: =N21-O21 -> 1998983 | S21: 45853 | T21: NO | X21: =VLOOKUP(W21,'2026 Calendar'!A:E,4,0) -> #N/A | Y21: =VLOOKUP(W21,'2026 Calendar'!A:B,2,0) -> #N/A | AC21: =VLOOKUP(AB21,'2026 Calendar'!A:E,4,0) -> #N/A | AD21: =VLOOKUP(AB21,'2026 Calendar'!A:B,2,0) -> #N/A | AF21: Approved | AG21: Approved | AH21: Approved | AI21: Approved | AK21: RSC purchase | AL21: RSC purchase | AQ21: 45931 | AR21: 45931
A22: =ROW(A22)-ROW($A$2) -> 20 | B22: Grey | C22: CANCELLED | D22: NON RH | E22: RFF-FLF | F22: FLEETWOOD FURNITURE | G22: MGM ARIA | H22: THƯ | I22: THƯ | J22: US | K22: DROPPED | L22: YES | N22: 6000000 | P22: =N22-O22 -> 6000000 | S22: 46045 | T22: NO | X22: =VLOOKUP(W22,'2026 Calendar'!A:E,4,0) -> #N/A | Y22: =VLOOKUP(W22,'2026 Calendar'!A:B,2,0) -> #N/A | AC22: =VLOOKUP(AB22,'2026 Calendar'!A:E,4,0) -> #N/A | AD22: =VLOOKUP(AB22,'2026 Calendar'!A:B,2,0) -> #N/A | AF22: Approved | AG22: Approved | AH22: WIP soucing | AI22: WIP soucing | AJ22: WIP soucing | AK22: RSC purchase | AL22: COM | AM22: Mock up no finishing | AQ22: 46060 | AR22: 45782
A23: =ROW(A23)-ROW($A$2) -> 21 | B23: Green | C23: COMPLETED | D23: NON RH | E23: RFF-FLF | F23: FLEETWOOD FURNITURE | G23: MGM ARIA | H23: THƯ | I23: THƯ | J23: US | K23: SAMPLE ROOM | L23: YES | M23: 2 | N23: 575.1 | O23: 575.1 | P23: =N23-O23 -> 0 | S23: 46045 | T23: YES | X23: =VLOOKUP(W23,'2026 Calendar'!A:E,4,0) -> #N/A | Y23: =VLOOKUP(W23,'2026 Calendar'!A:B,2,0) -> #N/A | AC23: =VLOOKUP(AB23,'2026 Calendar'!A:E,4,0) -> #N/A | AD23: =VLOOKUP(AB23,'2026 Calendar'!A:B,2,0) -> #N/A | AF23: Approved | AG23: Approved | AH23: WIP soucing | AI23: WIP soucing | AJ23: WIP soucing | AK23: RSC purchase | AL23: COM | AM23: Mock up no finishing | AQ23: 46060 | AR23: 45782
A24: =ROW(A24)-ROW($A$2) -> 22 | C24: IN PROGRESS | D24: NON RH | E24: RFF-MH | F24: MODERN HISTORY | G24: MH HOTEL PROJECT | H24: THƯ | I24: THƯ | J24: US | K24: PRODUCTION | L24: NO | M24: 6 | N24: 48755 | P24: =N24-O24 -> 48755 | S24: 46038 | T24: NO | X24: =VLOOKUP(W24,'2026 Calendar'!A:E,4,0) -> #N/A | Y24: =VLOOKUP(W24,'2026 Calendar'!A:B,2,0) -> #N/A | Z24: 46183 | AA24: June | AB24: NA | AC24: =VLOOKUP(AB24,'2026 Calendar'!A:E,4,0) -> #N/A | AD24: =VLOOKUP(AB24,'2026 Calendar'!A:B,2,0) -> #N/A | AF24: Approved | AG24: Approved | AH24: None | AI24: Approved | AJ24: None | AK24: None | AL24: None | AM24: COSTING STAGE, waiting for Luc confirmation for official PO | AQ24: 46188
A25: =ROW(A25)-ROW($A$2) -> 23 | B25: Yellow | C25: IN PROGRESS | D25: NON RH | E25: RFF-MOHI | F25: HOTEL MOHI C/O ABSOLUTE PROCUREMENT | G25: MOHI APPELLATION | H25: TUYẾT | I25: TUYẾT | J25: US | K25: PRODUCTION | M25: 32 | N25: 406396.56 | P25: =N25-O25 -> 406396.56 | R25: YES | S25: 46009 | X25: =VLOOKUP(W25,'2026 Calendar'!A:E,4,0) -> #N/A | Y25: =VLOOKUP(W25,'2026 Calendar'!A:B,2,0) -> #N/A | AC25: =VLOOKUP(AB25,'2026 Calendar'!A:E,4,0) -> #N/A | AD25: =VLOOKUP(AB25,'2026 Calendar'!A:B,2,0) -> #N/A | AF25: Pending approval | AG25: Approved | AH25: Approved | AI25: Approved | AJ25: Approved | AK25: Approved | AL25: RSC purchase | AM25: 13 drawings wait for client feedback | AQ25: 46142
A26: =ROW(A26)-ROW($A$2) -> 24 | C26: IN PROGRESS | D26: RH | E26: RFF-RH/HS | F26: RESTORATION HARDWARE_HS | G26: NAMA LISBON | H26: THƯ | I26: SƯƠNG | J26: PT | K26: PRODUCTION | L26: NO | M26: 11 | N26: 199073 | P26: =N26-O26 -> 199073 | S26: 46051 | T26: YES | U26: 46083 | X26: =VLOOKUP(W26,'2026 Calendar'!A:E,4,0) -> #N/A | Y26: =VLOOKUP(W26,'2026 Calendar'!A:B,2,0) -> #N/A | Z26: 46170 | AA26: May | AB26: W24 | AC26: =VLOOKUP(AB26,'2026 Calendar'!A:E,4,0) -> #N/A | AD26: =VLOOKUP(AB26,'2026 Calendar'!A:B,2,0) -> #N/A | AF26: Approved | AG26: Use available | AH26: None | AI26: Use available | AJ26: None | AK26: None | AL26: None | AQ26: 46203
A27: 34 | C27: IN PROGRESS | D27: NON RH | E27: TBC | F27: BROOKFILED PROPERTIES | G27: PARK HYATT VANCOUVER | H27: DŨNG | I27: DŨNG | J27: CA | K27: SAMPLE ROOM | L27: YES | M27: 9 | N27: 13096.1 | P27: =N27-O27 -> 13096.1 | R27: NO | S27: 46041 | T27: YES | U27: 46055 | X27: =VLOOKUP(W27,'2026 Calendar'!A:E,4,0) -> #N/A | Y27: =VLOOKUP(W27,'2026 Calendar'!A:B,2,0) -> #N/A | AC27: =VLOOKUP(AB27,'2026 Calendar'!A:E,4,0) -> #N/A | AD27: =VLOOKUP(AB27,'2026 Calendar'!A:B,2,0) -> #N/A | AF27: RSC WIP | AG27: Pending approval | AH27: Pending approval | AI27: WIP soucing | AJ27: WIP soucing | AK27: RSC purchase | AL27: COM | AM27: Awaiting order | AQ27: 46157
A28: =ROW(A28)-ROW($A$2) -> 26 | C28: IN PROGRESS | D28: RH | E28: RFF-RH/HS | F28: RESTORATION HARDWARE_HS | G28: RANCHO VALENCIA | H28: TUYẾT | I28: TUYẾT | J28: US | K28: PRODUCTION | L28: NO | M28: 1 | N28: 14520 | P28: =N28-O28 -> 14520 | S28: 46015 | T28: NO | X28: =VLOOKUP(W28,'2026 Calendar'!A:E,4,0) -> #N/A | Y28: =VLOOKUP(W28,'2026 Calendar'!A:B,2,0) -> #N/A | AC28: =VLOOKUP(AB28,'2026 Calendar'!A:E,4,0) -> #N/A | AD28: =VLOOKUP(AB28,'2026 Calendar'!A:B,2,0) -> #N/A | AF28: Pending approval | AG28: Pending approval | AH28: None | AI28: None | AJ28: None | AK28: None | AL28: RSC purchase | AQ28: N/A
A29: =ROW(A29)-ROW($A$2) -> 27 | C29: IN PROGRESS | D29: RH | E29: RFF-RH/HS | F29: RESTORATION HARDWARE_HS | G29: RH CASSIA CONDO | H29: TUYẾT | I29: TUYẾT | J29: US | K29: PRODUCTION | L29: NO | M29: 50 | N29: 1171637 | P29: =N29-O29 -> 1171637 | S29: 46023 | T29: NO | X29: =VLOOKUP(W29,'2026 Calendar'!A:E,4,0) -> #N/A | Y29: =VLOOKUP(W29,'2026 Calendar'!A:B,2,0) -> #N/A | AC29: =VLOOKUP(AB29,'2026 Calendar'!A:E,4,0) -> #N/A | AD29: =VLOOKUP(AB29,'2026 Calendar'!A:B,2,0) -> #N/A | AF29: Pending approval | AG29: Pending approval | AH29: None | AI29: Pending approval | AJ29: None | AK29: None | AL29: COM | AM29: RCS Cover and 3 types of COM, | AQ29: 46203
A30: =ROW(A30)-ROW($A$2) -> 28 | B30: Green | C30: IN PROGRESS | D30: RH | E30: RFF-RH/HS | F30: RESTORATION HARDWARE_HS | G30: RH contract | H30: THƯ | I30: SƯƠNG | J30: US | K30: PRODUCTION | L30: NO | M30: 1 | N30: 4200 | P30: =N30-O30 -> 4200 | Q30: NO REQUIRE | S30: N/A | T30: YES | U30: 46034 | X30: =VLOOKUP(W30,'2026 Calendar'!A:E,4,0) -> #N/A | Y30: =VLOOKUP(W30,'2026 Calendar'!A:B,2,0) -> #N/A | Z30: 46109 | AA30: March | AB30: W13 | AC30: =VLOOKUP(AB30,'2026 Calendar'!A:E,4,0) -> #N/A | AD30: =VLOOKUP(AB30,'2026 Calendar'!A:B,2,0) -> #N/A | AF30: Approved | AG30: Approved | AH30: None | AI30: None | AJ30: None | AK30: None | AL30: COM | AM30: CONTRACT STOCK | AQ30: 46109
A31: =ROW(A31)-ROW($A$2) -> 29 | C31: IN PROGRESS | D31: RH | E31: RFF-RH/HS | F31: RESTORATION HARDWARE_HS | G31: RH TRUMP SUITES NYC | H31: TUYẾT | I31: TUYẾT | J31: US | K31: PRODUCTION | L31: YES | M31: 51 | N31: 1653853 | P31: =N31-O31 -> 1653853 | S31: N/A | T31: NO | X31: =VLOOKUP(W31,'2026 Calendar'!A:E,4,0) -> #N/A | Y31: =VLOOKUP(W31,'2026 Calendar'!A:B,2,0) -> #N/A | AC31: =VLOOKUP(AB31,'2026 Calendar'!A:E,4,0) -> #N/A | AD31: =VLOOKUP(AB31,'2026 Calendar'!A:B,2,0) -> #N/A | AF31: Approved | AG31: Approved | AH31: Approved | AI31: Approved | AJ31: Approved | AK31: Approved | AL31: COM | AM31: * 21/51 drawings approved and shipped sample, Tuyet working on final BOQ to proceed more drawings for production * 9 types of COM, 12 types of RSC cover * The client is expecting to place the order for this project in June/July 2026. | AQ31: N/A
A32: =ROW(A32)-ROW($A$2) -> 30 | C32: IN PROGRESS | D32: NON RH | E32: RFF-TMSJ | F32: LANG & SCHWANDER | G32: RITZ CARLTON COTTON BAY | H32: NHI | I32: NHI | J32: US | K32: PRODUCTION | L32: YES | M32: 117 | N32: 2589501.9 | P32: =N32-O32 -> 2589501.9 | S32: 45730 | T32: NO | X32: =VLOOKUP(W32,'2026 Calendar'!A:E,4,0) -> #N/A | Y32: =VLOOKUP(W32,'2026 Calendar'!A:B,2,0) -> #N/A | AC32: =VLOOKUP(AB32,'2026 Calendar'!A:E,4,0) -> #N/A | AD32: =VLOOKUP(AB32,'2026 Calendar'!A:B,2,0) -> #N/A | AF32: Approved | AG32: Approved | AH32: Approved | AI32: Approved | AJ32: Approved | AK32: RSC purchase | AL32: COM | AQ32: N/A | AR32: 45861
A33: =ROW(A33)-ROW($A$2) -> 31 | C33: IN PROGRESS | D33: RH | E33: RFF-RH/HS | F33: RESTORATION HARDWARE_HS | G33: ROSEWOOD CALISTOGA | H33: NHI | I33: SƯƠNG | J33: US | K33: PRODUCTION | L33: NO | M33: 33 | N33: 367724.28 | P33: =N33-O33 -> 367724.28 | S33: 46036 | T33: NO | X33: =VLOOKUP(W33,'2026 Calendar'!A:E,4,0) -> #N/A | Y33: =VLOOKUP(W33,'2026 Calendar'!A:B,2,0) -> #N/A | AC33: =VLOOKUP(AB33,'2026 Calendar'!A:E,4,0) -> #N/A | AD33: =VLOOKUP(AB33,'2026 Calendar'!A:B,2,0) -> #N/A | AF33: RSC WIP | AG33: Use available | AH33: Pending approval | AI33: Use available | AJ33: None | AK33: None | AL33: COM | AQ33: N/A
A34: =ROW(A34)-ROW($A$2) -> 32 | C34: IN PROGRESS | D34: RH | E34: RFF-RH/HS | F34: RESTORATION HARDWARE_HS | G34: SNAKE RIVER LODGE BLUEFLAG | H34: TÚ ANH | I34: TÚ ANH | J34: US | K34: PRODUCTION | L34: YES | M34: 9 | N34: 381411.3 | P34: =N34-O34 -> 381411.3 | S34: 45800 | T34: NO | X34: =VLOOKUP(W34,'2026 Calendar'!A:E,4,0) -> #N/A | Y34: =VLOOKUP(W34,'2026 Calendar'!A:B,2,0) -> #N/A | AC34: =VLOOKUP(AB34,'2026 Calendar'!A:E,4,0) -> #N/A | AD34: =VLOOKUP(AB34,'2026 Calendar'!A:B,2,0) -> #N/A | AE34: Sea | AQ34: N/A | AR34: 45929
A35: =ROW(A35)-ROW($A$2) -> 33 | B35: Green | C35: IN PROGRESS | D35: NON RH | E35: RFF-PLUS | F35: PLUS CORPORATION | G35: SOHO HOUSE TOKYO+E25:P35 | H35: THẢO | I35: THẢO | J35: JP | K35: PRODUCTION | M35: 29 | N35: =126270.32+2668 -> 128938.32 | O35: 104926.32 | P35: =N35-O35 -> 24012 | Q35: 50% deposit, 50% prior shipment | R35: YES | S35: 45905 | T35: YES | U35: 46087 | X35: =VLOOKUP(W35,'2026 Calendar'!A:E,4,0) -> #N/A | Y35: =VLOOKUP(W35,'2026 Calendar'!A:B,2,0) -> #N/A | Z35: 46128 | AA35: April | AB35: W18 | AC35: 46141 | AD35: April | AE35: Airship | AF35: Approved | AG35: Approved | AH35: Approved | AI35: Approved | AJ35: Approved | AK35: None | AL35: COM | AQ35: 46128
A36: =ROW(A36)-ROW($A$2) -> 34 | B36: Red | C36: IN PROGRESS | D36: NON RH | E36: RFF-SK | F36: MBMA CORP. D/B/A SPECTRUM KITCHENS | G36: SPECTRUM KITCHENS | H36: THẢO | I36: THẢO | J36: US | K36: PRODUCTION | M36: 20 | N36: 94962.66 | P36: =N36-O36 -> 94962.66 | Q36: 50% deposit, 50% prior shipment | R36: NO | S36: 45961 | T36: YES | U36: 46306 | X36: =VLOOKUP(W36,'2026 Calendar'!A:E,4,0) -> #N/A | Y36: =VLOOKUP(W36,'2026 Calendar'!A:B,2,0) -> #N/A | Z36: 46199 | AA36: June | AC36: =VLOOKUP(#REF!,'2026 Calendar'!A:E,4,0) -> #REF! | AD36: =VLOOKUP(#REF!,'2026 Calendar'!A:B,2,0) -> #REF! | AF36: Pending approval | AG36: Pending approval | AH36: None | AI36: Pending approval | AJ36: None | AK36: None | AL36: None | AM36: BOQ updated 9-Mar. Pending planning cfm SW | AN36: Ship week 29 (7/19/26), approval and deposit deadline is W14. | AQ36: 46199
A37: =ROW(A37)-ROW($A$2) -> 35 | B37: Green | C37: IN PROGRESS | D37: NON RH | E37: RSC-MK | F37: MARKETING | G37: THẢO ĐIỀN OFFICE | H37: THẢO | I37: THẢO | J37: VN | K37: PRODUCTION | M37: 7 | N37: 12312 | O37: 2308.5 | P37: =N37-O37 -> 10003.5 | R37: NO | S37: 46029 | T37: NO | V37: 46164 | X37: =VLOOKUP(W37,'2026 Calendar'!A:E,4,0) -> #N/A | Y37: =VLOOKUP(W37,'2026 Calendar'!A:B,2,0) -> #N/A | AC37: =VLOOKUP(AB37,'2026 Calendar'!A:E,4,0) -> #N/A | AD37: =VLOOKUP(AB37,'2026 Calendar'!A:B,2,0) -> #N/A | AF37: Approved | AG37: Approved | AH37: Approved | AI37: None | AJ37: None | AK37: RSC purchase | AL37: None | AM37: Shipped Batch 1 | AQ37: 46059
A38: =ROW(A38)-ROW($A$2) -> 36 | C38: IN PROGRESS | D38: RH | E38: RFF-RH/HS | F38: RESTORATION HARDWARE_HS | G38: TRUMP LAS VEGAS PENTHOUSES | H38: NHI | I38: NHI | J38: US | K38: PRODUCTION | N38: 731096.8 | P38: =N38-O38 -> 731096.8 | Q38: NO REQUIRE | S38: N/A | T38: NO | X38: =VLOOKUP(W38,'2026 Calendar'!A:E,4,0) -> #N/A | Y38: =VLOOKUP(W38,'2026 Calendar'!A:B,2,0) -> #N/A | AC38: =VLOOKUP(AB38,'2026 Calendar'!A:E,4,0) -> #N/A | AD38: =VLOOKUP(AB38,'2026 Calendar'!A:B,2,0) -> #N/A | AQ38: N/A
A39: =ROW(A39)-ROW($A$2) -> 37 | B39: Green | C39: COMPLETED | D39: RH | E39: RFF-RH/HS | F39: RESTORATION HARDWARE_HS | G39: TRUMP LAS VEGAS PENTHOUSES | H39: NHI | I39: NHI | J39: US | K39: SAMPLE ROOM | L39: YES | M39: 15 | N39: 28773.56 | O39: 28773.56 | P39: =N39-O39 -> 0 | Q39: NO REQUIRE | S39: 45890 | X39: =VLOOKUP(W39,'2026 Calendar'!A:E,4,0) -> #N/A | Y39: =VLOOKUP(W39,'2026 Calendar'!A:B,2,0) -> #N/A | AC39: =VLOOKUP(AB39,'2026 Calendar'!A:E,4,0) -> #N/A | AD39: =VLOOKUP(AB39,'2026 Calendar'!A:B,2,0) -> #N/A | AF39: Approved | AG39: Approved | AH39: Approved | AI39: Approved | AJ39: Approved | AK39: Approved | AL39: COM | AM39: Shipped | AQ39: 46087
A40: =ROW(A40)-ROW($A$2) -> 38 | B40: Grey | C40: CANCELLED | D40: NON RH | E40: RFF-TMSJ | F40: LANG & SCHWANDER LLC | G40: WESTIN HOTEL COCOA BEACH | H40: SƯƠNG | I40: SƯƠNG | J40: US | K40: DROPPED | M40: 1 | N40: 3396.6 | P40: =N40-O40 -> 3396.6 | R40: YES | S40: 45846 | X40: =VLOOKUP(W40,'2026 Calendar'!A:E,4,0) -> #N/A | Y40: =VLOOKUP(W40,'2026 Calendar'!A:B,2,0) -> #N/A | AC40: =VLOOKUP(AB40,'2026 Calendar'!A:E,4,0) -> #N/A | AD40: =VLOOKUP(AB40,'2026 Calendar'!A:B,2,0) -> #N/A | AF40: Approved | AG40: Approved | AH40: None | AI40: None | AJ40: None | AK40: None | AL40: COM | AM40: Sample done. Wait for shipping instruction from customer | AQ40: 45666
...

Sheet Detail_New
A1: FORMULA | B1: DROP LIST | C1: MANUAL INPUT | H1: [YEAR]_[CUST NAME]_[PROJ-NAME]
A2: PROJECT TYPE | B2: STAGE | C2: PIC | D2: CUSTOMER PIC | E2: CUSTOMER NAME | F2: CUSTOMER SHORTEN NAME | G2: PROJECT NAME (SHORT) | H2: PROJECT NAME | I2: COUNT | J2: STATUS | K2: POOL | L2: NPD/NPI STAGE | M2: BOQ DATE | N2: PO RECEIVED DATE | O2: DEPOSIT RECEIVED DATE | P2: MARKET | Q2: MARKET STATE (US ONLY) | R2: BE SKU | S2: BE QTY | T2: CG QTY | U2: UPH QTY | V2: PROJECT SKU | W2: PROJECT QTY | X2: PROJECT VALUE $ | Y2: PROJECT BREAK VALUE | Z2: SHIP MONTH FC | AA2: SHIP YEAR | AB2: REQUESTED FIRST SD | AC2: REQUESTED LAST SD | AD2: CONFIRMED FIRST SD | AE2: CONFIRMED LAST SD | AF2: CONFIRMED FIRST SW | AG2: CONFIRMED LAST SW | AH2: DRAWING STATUS | AI2: DRAWING PLAN/DUE DATE | AJ2: DRAWING APPROVED DATE | AK2: VENEER/WOOD STATUS | AL2: VENEER/WOOD PLAN/DUE DATE | AM2: VENEER/WOOD APPROVED DATE | AN2: MARBLE STATUS | AO2: MARBLE PLAN/DUE DATE | AP2: MARBLE APPROVED DATE | AQ2: METAL STATUS | AR2: METAL PLAN/DUE DATE | AS2: METAL APPROVED DATE | AT2: MIRROR STATUS | AU2: MIRROR PLAN/DUE DATE | AV2: MIRROR APPROVED DATE | AW2: ELECTRICAL STATUS | AX2: ELECTRICAL PLAN/DUE DATE | AY2: ELECTRICAL APPROVED DATE | AZ2: FABRIC STATUS | BA2: FABRIC PLAN/DUE DATE | BB2: FABRIC DUE DATE | BC2: LIFECYCLE | BD2: CPSC + TSCA | BE2: DEVELOPMENT STATUS | BF2: Remarks
A3: =IFERROR(VLOOKUP(E3,'Customer '!$A$4:$D$23,3,FALSE),"") -> RH | B3: NPI | C3: TRINH | D3: Sue Bilstad | E3: RESTORATION HARDWARE_HS | F3: =IFERROR(VLOOKUP(E3,'Customer '!$A$4:$D$28,2,FALSE),"") -> RH | G3: GRAND HYATT BAHA MAR | H3: =IF(OR(DetailTracker[[#This Row],[PROJECT NAME (SHORT)]]="",DetailTracker[[#This Row],[CUSTOMER SHORTEN NAME]]=""),"",IF(ISNUMBER(DetailTracker[[#This Row],[BOQ DATE]]),YEAR(DetailTracker[[#This Row],[BOQ DATE]])&"-"&DetailTracker[[#This Row],[CUSTOMER SHORTEN NAME]]&"-"&DetailTracker[[#This Row],[PROJECT NAME (SHORT)]],IF(OR(DetailTracker[[#This Row],[SHIP MONTH FC]]="TBC",DetailTracker[[#This Row],[SHIP MONTH FC]]="Removed"),DetailTracker[[#This Row],[SHIP MONTH FC]]&"-"&DetailTracker[[#This Row],[CUSTOMER SHORTEN NAME]]&"-"&DetailTracker[[#This Row],[PROJECT NAME (SHORT)]],YEAR(TODAY())&"-"&DetailTracker[[#This Row],[CUSTOMER SHORTEN NAME]]&"-"&DetailTracker[[#This Row],[PROJECT NAME (SHORT)]]))) -> 2026-RH-GRAND HYATT BAHA MAR | I3: =IF(OR($H3="",$B3=""),0,--(COUNTIFS($H$3:$H3,$H3,$B$3:$B3,$B3)=1)) -> 1 | J3: SHIPPED | K3: NEW | L3: 8. Shipment | M3: 46033 | N3: 46098 | P3: BS | Q3: Bahamas | V3: 26 | X3: 2454228 | Y3: 153379 | Z3: 2026/M05 | AA3: =IF(Z3="","",IF(OR(Z3="TBC",Z3="Removed"),Z3,LEFT(Z3,4))) -> 2026 | AB3: 46167 | AC3: 46201 | AD3: 46173 | AE3: 46257 | AF3: =IF(AD3="","",IF(ISNUMBER(AD3),IF(AND(AD3>='2026 Calendar'!$C$4,AD3<='2026 Calendar'!$E$107),LOOKUP(AD3,'2026 Calendar'!$C$4:$C$107,'2026 Calendar'!$A$4:$A$107),YEAR(AD3-WEEKDAY(AD3,2)+4)&"/W"&TEXT(WEEKNUM(AD3,21),"00")),IF(IFERROR(ISNUMBER(SEARCH("/W",AD3)),FALSE),IF(IFERROR(ISNUMBER(SEARCH("-",AD3)),FALSE),LEFT(AD3,SEARCH("-",AD3)-1),AD3),AD3))) -> 2026/W22 | AG3: =IF(AE3="","",IF(ISNUMBER(AE3),IF(AND(AE3>='2026 Calendar'!$C$4,AE3<='2026 Calendar'!$E$107),LOOKUP(AE3,'2026 Calendar'!$C$4:$C$107,'2026 Calendar'!$A$4:$A$107),YEAR(AE3-WEEKDAY(AE3,2)+4)&"/W"&TEXT(WEEKNUM(AE3,21),"00")),IF(IFERROR(ISNUMBER(SEARCH("/W",AE3)),FALSE),IF(IFERROR(ISNUMBER(SEARCH("-",AE3)),FALSE),MID(AE3,SEARCH("-",AE3)+1,100),AE3),AE3))) -> 2026/W34 | AH3: Approved | AK3: Approved | AN3: Approved | AQ3: Approved | AT3: N/A | AW3: Approved | AZ3: COM Received | BC3: =IF(J3="","",IF(OR(J3="OB",J3="NOR",J3="FC",J3="PIPELINE"),"Active","Complete")) -> Complete | BD3: Yes | BE3: =IF(UPPER(TRIM(J3))="SHIPPED","READY",_xlfn.LET(_xlpm.stage,IF(B3="","",B3&": "),_xlpm.ip,_xlfn.TEXTJOIN(", ",TRUE,IF(LOWER(AH3)="in progress","Drawing",""),IF(LOWER(AK3)="in progress","Veneer/Wood",""),IF(LOWER(AN3)="in progress","Marble",""),IF(LOWER(AQ3)="in progress","Metal",""),IF(LOWER(AT3)="in progress","Mirror",""),IF(LOWER(AW3)="in progress","Electrical",""),IF(LOWER(AZ3)="in progress","Fabric","")),_xlpm.pa,_xlfn.TEXTJOIN(", ",TRUE,IF(LOWER(AH3)="pending approval","Drawing",""),IF(LOWER(AK3)="pending approval","Veneer/Wood",""),IF(LOWER(AN3)="pending approval","Marble",""),IF(LOWER(AQ3)="pending approval","Metal",""),IF(LOWER(AT3)="pending approval","Mirror",""),IF(LOWER(AW3)="pending approval","Electrical",""),IF(LOWER(AZ3)="pending approval","Fabric","")),_xlpm.ns,_xlfn.TEXTJOIN(", ",TRUE,IF(LOWER(AH3)="not started","Drawing",""),IF(LOWER(AK3)="not started","Veneer/Wood",""),IF(LOWER(AN3)="not started","Marble",""),IF(LOWER(AQ3)="not started","Metal",""),IF(LOWER(AT3)="not started","Mirror",""),IF(LOWER(AW3)="not started","Electrical",""),IF(LOWER(AZ3)="not started","Fabric","")),_xlpm.fab,IF(OR(LOWER(AZ3)="com",LOWER(AZ3)="com pending",LOWER(AZ3)="com received"),"Fabric is "&LOWER(AZ3),""),_xlpm.parts,_xlfn.TEXTJOIN("; ",TRUE,IF(_xlpm.ip<>"","In progress: "&_xlpm.ip,""),IF(_xlpm.pa<>"","Pending approval: "&_xlpm.pa,""),IF(_xlpm.ns<>"","Not started: "&_xlpm.ns,""),_xlpm.fab),_xlpm.deadline,MIN(IF(AND(AH3<>"",LOWER(AH3)<>"approved",LOWER(AH3)<>"n/a",ISNUMBER(AI3)),AI3,1E+99),IF(AND(AK3<>"",LOWER(AK3)<>"approved",LOWER(AK3)<>"n/a",ISNUMBER(AL3)),AL3,1E+99),IF(AND(AN3<>"",LOWER(AN3)<>"approved",LOWER(AN3)<>"n/a",ISNUMBER(AO3)),AO3,1E+99),IF(AND(AQ3<>"",LOWER(AQ3)<>"approved",LOWER(AQ3)<>"n/a",ISNUMBER(AR3)),AR3,1E+99),IF(AND(AT3<>"",LOWER(AT3)<>"approved",LOWER(AT3)<>"n/a",ISNUMBER(AU3)),AU3,1E+99),IF(AND(AW3<>"",LOWER(AW3)<>"approved",LOWER(AW3)<>"n/a",ISNUMBER(AX3)),AX3,1E+99),IF(AND(AZ3<>"",LOWER(AZ3)<>"approved",LOWER(AZ3)<>"n/a",ISNUMBER(BA3)),BA3,1E+99)),_xlpm.sw,IF(AG3="","",IFERROR("SW"&MID(AG3,FIND("/W",AG3)+2,99),"SW "&AG3)),_xlpm.stage&IF(_xlpm.parts="","All development items approved/closed",_xlpm.parts)&IF(AND(_xlpm.parts<>"",_xlpm.deadline<1E+99),"; need approval by "&TEXT(_xlpm.deadline,"d-mmm-yy"),"")&IF(_xlpm.sw<>""," for "&_xlpm.sw,""))) -> READY
A4: =IFERROR(VLOOKUP(E4,'Customer '!$A$4:$D$23,3,FALSE),"") -> RH | B4: NPI | C4: TRINH | D4: Sue Bilstad | E4: RESTORATION HARDWARE_HS | F4: =IFERROR(VLOOKUP(E4,'Customer '!$A$4:$D$28,2,FALSE),"") -> RH | G4: GRAND HYATT BAHA MAR | H4: =IF(OR(DetailTracker[[#This Row],[PROJECT NAME (SHORT)]]="",DetailTracker[[#This Row],[CUSTOMER SHORTEN NAME]]=""),"",IF(ISNUMBER(DetailTracker[[#This Row],[BOQ DATE]]),YEAR(DetailTracker[[#This Row],[BOQ DATE]])&"-"&DetailTracker[[#This Row],[CUSTOMER SHORTEN NAME]]&"-"&DetailTracker[[#This Row],[PROJECT NAME (SHORT)]],IF(OR(DetailTracker[[#This Row],[SHIP MONTH FC]]="TBC",DetailTracker[[#This Row],[SHIP MONTH FC]]="Removed"),DetailTracker[[#This Row],[SHIP MONTH FC]]&"-"&DetailTracker[[#This Row],[CUSTOMER SHORTEN NAME]]&"-"&DetailTracker[[#This Row],[PROJECT NAME (SHORT)]],YEAR(TODAY())&"-"&DetailTracker[[#This Row],[CUSTOMER SHORTEN NAME]]&"-"&DetailTracker[[#This Row],[PROJECT NAME (SHORT)]]))) -> 2026-RH-GRAND HYATT BAHA MAR | I4: =IF(OR($H4="",$B4=""),0,--(COUNTIFS($H$3:$H4,$H4,$B$3:$B4,$B4)=1)) -> 1 | J4: SHIPPED | K4: NEW | L4: 8. Shipment | M4: 46033 | N4: 46098 | P4: BS | Q4: Bahamas | V4: 26 | X4: 2454228 | Y4: 1004676 | Z4: 2026/M06 | AA4: =IF(Z4="","",IF(OR(Z4="TBC",Z4="Removed"),Z4,LEFT(Z4,4))) -> 2026 | AB4: 46167 | AC4: 46201 | AD4: 46173 | AE4: 46257 | AF4: =IF(AD4="","",IF(ISNUMBER(AD4),IF(AND(AD4>='2026 Calendar'!$C$4,AD4<='2026 Calendar'!$E$107),LOOKUP(AD4,'2026 Calendar'!$C$4:$C$107,'2026 Calendar'!$A$4:$A$107),YEAR(AD4-WEEKDAY(AD4,2)+4)&"/W"&TEXT(WEEKNUM(AD4,21),"00")),IF(IFERROR(ISNUMBER(SEARCH("/W",AD4)),FALSE),IF(IFERROR(ISNUMBER(SEARCH("-",AD4)),FALSE),LEFT(AD4,SEARCH("-",AD4)-1),AD4),AD4))) -> 2026/W22 | AG4: =IF(AE4="","",IF(ISNUMBER(AE4),IF(AND(AE4>='2026 Calendar'!$C$4,AE4<='2026 Calendar'!$E$107),LOOKUP(AE4,'2026 Calendar'!$C$4:$C$107,'2026 Calendar'!$A$4:$A$107),YEAR(AE4-WEEKDAY(AE4,2)+4)&"/W"&TEXT(WEEKNUM(AE4,21),"00")),IF(IFERROR(ISNUMBER(SEARCH("/W",AE4)),FALSE),IF(IFERROR(ISNUMBER(SEARCH("-",AE4)),FALSE),MID(AE4,SEARCH("-",AE4)+1,100),AE4),AE4))) -> 2026/W34 | AH4: Approved | AK4: Approved | AN4: Approved | AQ4: Approved | AT4: N/A | AW4: Approved | AZ4: COM Received | BC4: =IF(J4="","",IF(OR(J4="OB",J4="NOR",J4="FC",J4="PIPELINE"),"Active","Complete")) -> Complete | BD4: Yes | BE4: =IF(UPPER(TRIM(J4))="SHIPPED","READY",_xlfn.LET(_xlpm.stage,IF(B4="","",B4&": "),_xlpm.ip,_xlfn.TEXTJOIN(", ",TRUE,IF(LOWER(AH4)="in progress","Drawing",""),IF(LOWER(AK4)="in progress","Veneer/Wood",""),IF(LOWER(AN4)="in progress","Marble",""),IF(LOWER(AQ4)="in progress","Metal",""),IF(LOWER(AT4)="in progress","Mirror",""),IF(LOWER(AW4)="in progress","Electrical",""),IF(LOWER(AZ4)="in progress","Fabric","")),_xlpm.pa,_xlfn.TEXTJOIN(", ",TRUE,IF(LOWER(AH4)="pending approval","Drawing",""),IF(LOWER(AK4)="pending approval","Veneer/Wood",""),IF(LOWER(AN4)="pending approval","Marble",""),IF(LOWER(AQ4)="pending approval","Metal",""),IF(LOWER(AT4)="pending approval","Mirror",""),IF(LOWER(AW4)="pending approval","Electrical",""),IF(LOWER(AZ4)="pending approval","Fabric","")),_xlpm.ns,_xlfn.TEXTJOIN(", ",TRUE,IF(LOWER(AH4)="not started","Drawing",""),IF(LOWER(AK4)="not started","Veneer/Wood",""),IF(LOWER(AN4)="not started","Marble",""),IF(LOWER(AQ4)="not started","Metal",""),IF(LOWER(AT4)="not started","Mirror",""),IF(LOWER(AW4)="not started","Electrical",""),IF(LOWER(AZ4)="not started","Fabric","")),_xlpm.fab,IF(OR(LOWER(AZ4)="com",LOWER(AZ4)="com pending",LOWER(AZ4)="com received"),"Fabric is "&LOWER(AZ4),""),_xlpm.parts,_xlfn.TEXTJOIN("; ",TRUE,IF(_xlpm.ip<>"","In progress: "&_xlpm.ip,""),IF(_xlpm.pa<>"","Pending approval: "&_xlpm.pa,""),IF(_xlpm.ns<>"","Not started: "&_xlpm.ns,""),_xlpm.fab),_xlpm.deadline,MIN(IF(AND(AH4<>"",LOWER(AH4)<>"approved",LOWER(AH4)<>"n/a",ISNUMBER(AI4)),AI4,1E+99),IF(AND(AK4<>"",LOWER(AK4)<>"approved",LOWER(AK4)<>"n/a",ISNUMBER(AL4)),AL4,1E+99),IF(AND(AN4<>"",LOWER(AN4)<>"approved",LOWER(AN4)<>"n/a",ISNUMBER(AO4)),AO4,1E+99),IF(AND(AQ4<>"",LOWER(AQ4)<>"approved",LOWER(AQ4)<>"n/a",ISNUMBER(AR4)),AR4,1E+99),IF(AND(AT4<>"",LOWER(AT4)<>"approved",LOWER(AT4)<>"n/a",ISNUMBER(AU4)),AU4,1E+99),IF(AND(AW4<>"",LOWER(AW4)<>"approved",LOWER(AW4)<>"n/a",ISNUMBER(AX4)),AX4,1E+99),IF(AND(AZ4<>"",LOWER(AZ4)<>"approved",LOWER(AZ4)<>"n/a",ISNUMBER(BA4)),BA4,1E+99)),_xlpm.sw,IF(AG4="","",IFERROR("SW"&MID(AG4,FIND("/W",AG4)+2,99),"SW "&AG4)),_xlpm.stage&IF(_xlpm.parts="","All development items approved/closed",_xlpm.parts)&IF(AND(_xlpm.parts<>"",_xlpm.deadline<1E+99),"; need approval by "&TEXT(_xlpm.deadline,"d-mmm-yy"),"")&IF(_xlpm.sw<>""," for "&_xlpm.sw,""))) -> READY
A5: =IFERROR(VLOOKUP(E5,'Customer '!$A$4:$D$23,3,FALSE),"") -> RH | B5: NPI | C5: TRINH | D5: Sue Bilstad | E5: RESTORATION HARDWARE_HS | F5: =IFERROR(VLOOKUP(E5,'Customer '!$A$4:$D$28,2,FALSE),"") -> RH | G5: GRAND HYATT BAHA MAR | H5: =IF(OR(DetailTracker[[#This Row],[PROJECT NAME (SHORT)]]="",DetailTracker[[#This Row],[CUSTOMER SHORTEN NAME]]=""),"",IF(ISNUMBER(DetailTracker[[#This Row],[BOQ DATE]]),YEAR(DetailTracker[[#This Row],[BOQ DATE]])&"-"&DetailTracker[[#This Row],[CUSTOMER SHORTEN NAME]]&"-"&DetailTracker[[#This Row],[PROJECT NAME (SHORT)]],IF(OR(DetailTracker[[#This Row],[SHIP MONTH FC]]="TBC",DetailTracker[[#This Row],[SHIP MONTH FC]]="Removed"),DetailTracker[[#This Row],[SHIP MONTH FC]]&"-"&DetailTracker[[#This Row],[CUSTOMER SHORTEN NAME]]&"-"&DetailTracker[[#This Row],[PROJECT NAME (SHORT)]],YEAR(TODAY())&"-"&DetailTracker[[#This Row],[CUSTOMER SHORTEN NAME]]&"-"&DetailTracker[[#This Row],[PROJECT NAME (SHORT)]]))) -> 2026-RH-GRAND HYATT BAHA MAR | I5: =IF(OR($H5="",$B5=""),0,--(COUNTIFS($H$3:$H5,$H5,$B$3:$B5,$B5)=1)) -> 0 | J5: SHIPPED | K5: NEW | L5: 8. Shipment | M5: 46033 | N5: 46098 | P5: BS | Q5: Bahamas | V5: 26 | X5: 2454228 | Y5: 969712.83 | Z5: 2026/M07 | AA5: =IF(Z5="","",IF(OR(Z5="TBC",Z5="Removed"),Z5,LEFT(Z5,4))) -> 2026 | AB5: 46167 | AC5: 46201 | AD5: 46173 | AE5: 46257 | AF5: =IF(AD5="","",IF(ISNUMBER(AD5),IF(AND(AD5>='2026 Calendar'!$C$4,AD5<='2026 Calendar'!$E$107),LOOKUP(AD5,'2026 Calendar'!$C$4:$C$107,'2026 Calendar'!$A$4:$A$107),YEAR(AD5-WEEKDAY(AD5,2)+4)&"/W"&TEXT(WEEKNUM(AD5,21),"00")),IF(IFERROR(ISNUMBER(SEARCH("/W",AD5)),FALSE),IF(IFERROR(ISNUMBER(SEARCH("-",AD5)),FALSE),LEFT(AD5,SEARCH("-",AD5)-1),AD5),AD5))) -> 2026/W22 | AG5: =IF(AE5="","",IF(ISNUMBER(AE5),IF(AND(AE5>='2026 Calendar'!$C$4,AE5<='2026 Calendar'!$E$107),LOOKUP(AE5,'2026 Calendar'!$C$4:$C$107,'2026 Calendar'!$A$4:$A$107),YEAR(AE5-WEEKDAY(AE5,2)+4)&"/W"&TEXT(WEEKNUM(AE5,21),"00")),IF(IFERROR(ISNUMBER(SEARCH("/W",AE5)),FALSE),IF(IFERROR(ISNUMBER(SEARCH("-",AE5)),FALSE),MID(AE5,SEARCH("-",AE5)+1,100),AE5),AE5))) -> 2026/W34 | AH5: Approved | AK5: Approved | AN5: Approved | AQ5: Approved | AT5: N/A | AW5: Approved | AZ5: COM Received | BC5: =IF(J5="","",IF(OR(J5="OB",J5="NOR",J5="FC",J5="PIPELINE"),"Active","Complete")) -> Complete | BD5: Yes | BE5: =IF(UPPER(TRIM(J5))="SHIPPED","READY",_xlfn.LET(_xlpm.stage,IF(B5="","",B5&": "),_xlpm.ip,_xlfn.TEXTJOIN(", ",TRUE,IF(LOWER(AH5)="in progress","Drawing",""),IF(LOWER(AK5)="in progress","Veneer/Wood",""),IF(LOWER(AN5)="in progress","Marble",""),IF(LOWER(AQ5)="in progress","Metal",""),IF(LOWER(AT5)="in progress","Mirror",""),IF(LOWER(AW5)="in progress","Electrical",""),IF(LOWER(AZ5)="in progress","Fabric","")),_xlpm.pa,_xlfn.TEXTJOIN(", ",TRUE,IF(LOWER(AH5)="pending approval","Drawing",""),IF(LOWER(AK5)="pending approval","Veneer/Wood",""),IF(LOWER(AN5)="pending approval","Marble",""),IF(LOWER(AQ5)="pending approval","Metal",""),IF(LOWER(AT5)="pending approval","Mirror",""),IF(LOWER(AW5)="pending approval","Electrical",""),IF(LOWER(AZ5)="pending approval","Fabric","")),_xlpm.ns,_xlfn.TEXTJOIN(", ",TRUE,IF(LOWER(AH5)="not started","Drawing",""),IF(LOWER(AK5)="not started","Veneer/Wood",""),IF(LOWER(AN5)="not started","Marble",""),IF(LOWER(AQ5)="not started","Metal",""),IF(LOWER(AT5)="not started","Mirror",""),IF(LOWER(AW5)="not started","Electrical",""),IF(LOWER(AZ5)="not started","Fabric","")),_xlpm.fab,IF(OR(LOWER(AZ5)="com",LOWER(AZ5)="com pending",LOWER(AZ5)="com received"),"Fabric is "&LOWER(AZ5),""),_xlpm.parts,_xlfn.TEXTJOIN("; ",TRUE,IF(_xlpm.ip<>"","In progress: "&_xlpm.ip,""),IF(_xlpm.pa<>"","Pending approval: "&_xlpm.pa,""),IF(_xlpm.ns<>"","Not started: "&_xlpm.ns,""),_xlpm.fab),_xlpm.deadline,MIN(IF(AND(AH5<>"",LOWER(AH5)<>"approved",LOWER(AH5)<>"n/a",ISNUMBER(AI5)),AI5,1E+99),IF(AND(AK5<>"",LOWER(AK5)<>"approved",LOWER(AK5)<>"n/a",ISNUMBER(AL5)),AL5,1E+99),IF(AND(AN5<>"",LOWER(AN5)<>"approved",LOWER(AN5)<>"n/a",ISNUMBER(AO5)),AO5,1E+99),IF(AND(AQ5<>"",LOWER(AQ5)<>"approved",LOWER(AQ5)<>"n/a",ISNUMBER(AR5)),AR5,1E+99),IF(AND(AT5<>"",LOWER(AT5)<>"approved",LOWER(AT5)<>"n/a",ISNUMBER(AU5)),AU5,1E+99),IF(AND(AW5<>"",LOWER(AW5)<>"approved",LOWER(AW5)<>"n/a",ISNUMBER(AX5)),AX5,1E+99),IF(AND(AZ5<>"",LOWER(AZ5)<>"approved",LOWER(AZ5)<>"n/a",ISNUMBER(BA5)),BA5,1E+99)),_xlpm.sw,IF(AG5="","",IFERROR("SW"&MID(AG5,FIND("/W",AG5)+2,99),"SW "&AG5)),_xlpm.stage&IF(_xlpm.parts="","All development items approved/closed",_xlpm.parts)&IF(AND(_xlpm.parts<>"",_xlpm.deadline<1E+99),"; need approval by "&TEXT(_xlpm.deadline,"d-mmm-yy"),"")&IF(_xlpm.sw<>""," for "&_xlpm.sw,""))) -> READY
A6: =IFERROR(VLOOKUP(E6,'Customer '!$A$4:$D$23,3,FALSE),"") -> RH | B6: NPI | C6: TRINH | D6: Sue Bilstad | E6: RESTORATION HARDWARE_HS | F6: =IFERROR(VLOOKUP(E6,'Customer '!$A$4:$D$28,2,FALSE),"") -> RH | G6: GRAND HYATT BAHA MAR | H6: =IF(OR(DetailTracker[[#This Row],[PROJECT NAME (SHORT)]]="",DetailTracker[[#This Row],[CUSTOMER SHORTEN NAME]]=""),"",IF(ISNUMBER(DetailTracker[[#This Row],[BOQ DATE]]),YEAR(DetailTracker[[#This Row],[BOQ DATE]])&"-"&DetailTracker[[#This Row],[CUSTOMER SHORTEN NAME]]&"-"&DetailTracker[[#This Row],[PROJECT NAME (SHORT)]],IF(OR(DetailTracker[[#This Row],[SHIP MONTH FC]]="TBC",DetailTracker[[#This Row],[SHIP MONTH FC]]="Removed"),DetailTracker[[#This Row],[SHIP MONTH FC]]&"-"&DetailTracker[[#This Row],[CUSTOMER SHORTEN NAME]]&"-"&DetailTracker[[#This Row],[PROJECT NAME (SHORT)]],YEAR(TODAY())&"-"&DetailTracker[[#This Row],[CUSTOMER SHORTEN NAME]]&"-"&DetailTracker[[#This Row],[PROJECT NAME (SHORT)]]))) -> 2026-RH-GRAND HYATT BAHA MAR | I6: =IF(OR($H6="",$B6=""),0,--(COUNTIFS($H$3:$H6,$H6,$B$3:$B6,$B6)=1)) -> 0 | J6: SHIPPED | K6: NEW | L6: 8. Shipment | M6: 46033 | N6: 46098 | P6: BS | Q6: Bahamas | V6: 26 | X6: 2454228 | Y6: 308393 | Z6: 2026/M08 | AA6: =IF(Z6="","",IF(OR(Z6="TBC",Z6="Removed"),Z6,LEFT(Z6,4))) -> 2026 | AB6: 46167 | AC6: 46201 | AD6: 46173 | AE6: 46257 | AF6: =IF(AD6="","",IF(ISNUMBER(AD6),IF(AND(AD6>='2026 Calendar'!$C$4,AD6<='2026 Calendar'!$E$107),LOOKUP(AD6,'2026 Calendar'!$C$4:$C$107,'2026 Calendar'!$A$4:$A$107),YEAR(AD6-WEEKDAY(AD6,2)+4)&"/W"&TEXT(WEEKNUM(AD6,21),"00")),IF(IFERROR(ISNUMBER(SEARCH("/W",AD6)),FALSE),IF(IFERROR(ISNUMBER(SEARCH("-",AD6)),FALSE),LEFT(AD6,SEARCH("-",AD6)-1),AD6),AD6))) -> 2026/W22 | AG6: =IF(AE6="","",IF(ISNUMBER(AE6),IF(AND(AE6>='2026 Calendar'!$C$4,AE6<='2026 Calendar'!$E$107),LOOKUP(AE6,'2026 Calendar'!$C$4:$C$107,'2026 Calendar'!$A$4:$A$107),YEAR(AE6-WEEKDAY(AE6,2)+4)&"/W"&TEXT(WEEKNUM(AE6,21),"00")),IF(IFERROR(ISNUMBER(SEARCH("/W",AE6)),FALSE),IF(IFERROR(ISNUMBER(SEARCH("-",AE6)),FALSE),MID(AE6,SEARCH("-",AE6)+1,100),AE6),AE6))) -> 2026/W34 | AH6: Approved | AK6: Approved | AN6: Approved | AQ6: Approved | AT6: N/A | AW6: Approved | AZ6: COM Received | BC6: =IF(J6="","",IF(OR(J6="OB",J6="NOR",J6="FC",J6="PIPELINE"),"Active","Complete")) -> Complete | BD6: Yes | BE6: =IF(UPPER(TRIM(J6))="SHIPPED","READY",_xlfn.LET(_xlpm.stage,IF(B6="","",B6&": "),_xlpm.ip,_xlfn.TEXTJOIN(", ",TRUE,IF(LOWER(AH6)="in progress","Drawing",""),IF(LOWER(AK6)="in progress","Veneer/Wood",""),IF(LOWER(AN6)="in progress","Marble",""),IF(LOWER(AQ6)="in progress","Metal",""),IF(LOWER(AT6)="in progress","Mirror",""),IF(LOWER(AW6)="in progress","Electrical",""),IF(LOWER(AZ6)="in progress","Fabric","")),_xlpm.pa,_xlfn.TEXTJOIN(", ",TRUE,IF(LOWER(AH6)="pending approval","Drawing",""),IF(LOWER(AK6)="pending approval","Veneer/Wood",""),IF(LOWER(AN6)="pending approval","Marble",""),IF(LOWER(AQ6)="pending approval","Metal",""),IF(LOWER(AT6)="pending approval","Mirror",""),IF(LOWER(AW6)="pending approval","Electrical",""),IF(LOWER(AZ6)="pending approval","Fabric","")),_xlpm.ns,_xlfn.TEXTJOIN(", ",TRUE,IF(LOWER(AH6)="not started","Drawing",""),IF(LOWER(AK6)="not started","Veneer/Wood",""),IF(LOWER(AN6)="not started","Marble",""),IF(LOWER(AQ6)="not started","Metal",""),IF(LOWER(AT6)="not started","Mirror",""),IF(LOWER(AW6)="not started","Electrical",""),IF(LOWER(AZ6)="not started","Fabric","")),_xlpm.fab,IF(OR(LOWER(AZ6)="com",LOWER(AZ6)="com pending",LOWER(AZ6)="com received"),"Fabric is "&LOWER(AZ6),""),_xlpm.parts,_xlfn.TEXTJOIN("; ",TRUE,IF(_xlpm.ip<>"","In progress: "&_xlpm.ip,""),IF(_xlpm.pa<>"","Pending approval: "&_xlpm.pa,""),IF(_xlpm.ns<>"","Not started: "&_xlpm.ns,""),_xlpm.fab),_xlpm.deadline,MIN(IF(AND(AH6<>"",LOWER(AH6)<>"approved",LOWER(AH6)<>"n/a",ISNUMBER(AI6)),AI6,1E+99),IF(AND(AK6<>"",LOWER(AK6)<>"approved",LOWER(AK6)<>"n/a",ISNUMBER(AL6)),AL6,1E+99),IF(AND(AN6<>"",LOWER(AN6)<>"approved",LOWER(AN6)<>"n/a",ISNUMBER(AO6)),AO6,1E+99),IF(AND(AQ6<>"",LOWER(AQ6)<>"approved",LOWER(AQ6)<>"n/a",ISNUMBER(AR6)),AR6,1E+99),IF(AND(AT6<>"",LOWER(AT6)<>"approved",LOWER(AT6)<>"n/a",ISNUMBER(AU6)),AU6,1E+99),IF(AND(AW6<>"",LOWER(AW6)<>"approved",LOWER(AW6)<>"n/a",ISNUMBER(AX6)),AX6,1E+99),IF(AND(AZ6<>"",LOWER(AZ6)<>"approved",LOWER(AZ6)<>"n/a",ISNUMBER(BA6)),BA6,1E+99)),_xlpm.sw,IF(AG6="","",IFERROR("SW"&MID(AG6,FIND("/W",AG6)+2,99),"SW "&AG6)),_xlpm.stage&IF(_xlpm.parts="","All development items approved/closed",_xlpm.parts)&IF(AND(_xlpm.parts<>"",_xlpm.deadline<1E+99),"; need approval by "&TEXT(_xlpm.deadline,"d-mmm-yy"),"")&IF(_xlpm.sw<>""," for "&_xlpm.sw,""))) -> READY
A7: =IFERROR(VLOOKUP(E7,'Customer '!$A$4:$D$23,3,FALSE),"") -> RH | B7: NPI | C7: TRINH | D7: Sue Bilstad | E7: RESTORATION HARDWARE_HS | F7: =IFERROR(VLOOKUP(E7,'Customer '!$A$4:$D$28,2,FALSE),"") -> RH | G7: GRAND HYATT BAHA MAR | H7: =IF(OR(DetailTracker[[#This Row],[PROJECT NAME (SHORT)]]="",DetailTracker[[#This Row],[CUSTOMER SHORTEN NAME]]=""),"",IF(ISNUMBER(DetailTracker[[#This Row],[BOQ DATE]]),YEAR(DetailTracker[[#This Row],[BOQ DATE]])&"-"&DetailTracker[[#This Row],[CUSTOMER SHORTEN NAME]]&"-"&DetailTracker[[#This Row],[PROJECT NAME (SHORT)]],IF(OR(DetailTracker[[#This Row],[SHIP MONTH FC]]="TBC",DetailTracker[[#This Row],[SHIP MONTH FC]]="Removed"),DetailTracker[[#This Row],[SHIP MONTH FC]]&"-"&DetailTracker[[#This Row],[CUSTOMER SHORTEN NAME]]&"-"&DetailTracker[[#This Row],[PROJECT NAME (SHORT)]],YEAR(TODAY())&"-"&DetailTracker[[#This Row],[CUSTOMER SHORTEN NAME]]&"-"&DetailTracker[[#This Row],[PROJECT NAME (SHORT)]]))) -> 2026-RH-GRAND HYATT BAHA MAR | I7: =IF(OR($H7="",$B7=""),0,--(COUNTIFS($H$3:$H7,$H7,$B$3:$B7,$B7)=1)) -> 0 | J7: SHIPPED | K7: NEW | L7: 8. Shipment | M7: 46033 | N7: 46098 | P7: BS | Q7: Bahamas | R7: 0 | S7: 0 | V7: 26 | X7: 2454228 | Y7: 18067 | Z7: 2026/M08 | AA7: =IF(Z7="","",IF(OR(Z7="TBC",Z7="Removed"),Z7,LEFT(Z7,4))) -> 2026 | AB7: 46167 | AC7: 46201 | AD7: 46173 | AE7: 46257 | AF7: =IF(AD7="","",IF(ISNUMBER(AD7),IF(AND(AD7>='2026 Calendar'!$C$4,AD7<='2026 Calendar'!$E$107),LOOKUP(AD7,'2026 Calendar'!$C$4:$C$107,'2026 Calendar'!$A$4:$A$107),YEAR(AD7-WEEKDAY(AD7,2)+4)&"/W"&TEXT(WEEKNUM(AD7,21),"00")),IF(IFERROR(ISNUMBER(SEARCH("/W",AD7)),FALSE),IF(IFERROR(ISNUMBER(SEARCH("-",AD7)),FALSE),LEFT(AD7,SEARCH("-",AD7)-1),AD7),AD7))) -> 2026/W22 | AG7: =IF(AE7="","",IF(ISNUMBER(AE7),IF(AND(AE7>='2026 Calendar'!$C$4,AE7<='2026 Calendar'!$E$107),LOOKUP(AE7,'2026 Calendar'!$C$4:$C$107,'2026 Calendar'!$A$4:$A$107),YEAR(AE7-WEEKDAY(AE7,2)+4)&"/W"&TEXT(WEEKNUM(AE7,21),"00")),IF(IFERROR(ISNUMBER(SEARCH("/W",AE7)),FALSE),IF(IFERROR(ISNUMBER(SEARCH("-",AE7)),FALSE),MID(AE7,SEARCH("-",AE7)+1,100),AE7),AE7))) -> 2026/W34 | AH7: Approved | AK7: Approved | AN7: Approved | AQ7: Approved | AT7: N/A | AW7: Approved | AZ7: COM Received | BC7: =IF(J7="","",IF(OR(J7="OB",J7="NOR",J7="FC",J7="PIPELINE"),"Active","Complete")) -> Complete | BD7: Yes | BE7: =IF(UPPER(TRIM(J7))="SHIPPED","READY",_xlfn.LET(_xlpm.stage,IF(B7="","",B7&": "),_xlpm.ip,_xlfn.TEXTJOIN(", ",TRUE,IF(LOWER(AH7)="in progress","Drawing",""),IF(LOWER(AK7)="in progress","Veneer/Wood",""),IF(LOWER(AN7)="in progress","Marble",""),IF(LOWER(AQ7)="in progress","Metal",""),IF(LOWER(AT7)="in progress","Mirror",""),IF(LOWER(AW7)="in progress","Electrical",""),IF(LOWER(AZ7)="in progress","Fabric","")),_xlpm.pa,_xlfn.TEXTJOIN(", ",TRUE,IF(LOWER(AH7)="pending approval","Drawing",""),IF(LOWER(AK7)="pending approval","Veneer/Wood",""),IF(LOWER(AN7)="pending approval","Marble",""),IF(LOWER(AQ7)="pending approval","Metal",""),IF(LOWER(AT7)="pending approval","Mirror",""),IF(LOWER(AW7)="pending approval","Electrical",""),IF(LOWER(AZ7)="pending approval","Fabric","")),_xlpm.ns,_xlfn.TEXTJOIN(", ",TRUE,IF(LOWER(AH7)="not started","Drawing",""),IF(LOWER(AK7)="not started","Veneer/Wood",""),IF(LOWER(AN7)="not started","Marble",""),IF(LOWER(AQ7)="not started","Metal",""),IF(LOWER(AT7)="not started","Mirror",""),IF(LOWER(AW7)="not started","Electrical",""),IF(LOWER(AZ7)="not started","Fabric","")),_xlpm.fab,IF(OR(LOWER(AZ7)="com",LOWER(AZ7)="com pending",LOWER(AZ7)="com received"),"Fabric is "&LOWER(AZ7),""),_xlpm.parts,_xlfn.TEXTJOIN("; ",TRUE,IF(_xlpm.ip<>"","In progress: "&_xlpm.ip,""),IF(_xlpm.pa<>"","Pending approval: "&_xlpm.pa,""),IF(_xlpm.ns<>"","Not started: "&_xlpm.ns,""),_xlpm.fab),_xlpm.deadline,MIN(IF(AND(AH7<>"",LOWER(AH7)<>"approved",LOWER(AH7)<>"n/a",ISNUMBER(AI7)),AI7,1E+99),IF(AND(AK7<>"",LOWER(AK7)<>"approved",LOWER(AK7)<>"n/a",ISNUMBER(AL7)),AL7,1E+99),IF(AND(AN7<>"",LOWER(AN7)<>"approved",LOWER(AN7)<>"n/a",ISNUMBER(AO7)),AO7,1E+99),IF(AND(AQ7<>"",LOWER(AQ7)<>"approved",LOWER(AQ7)<>"n/a",ISNUMBER(AR7)),AR7,1E+99),IF(AND(AT7<>"",LOWER(AT7)<>"approved",LOWER(AT7)<>"n/a",ISNUMBER(AU7)),AU7,1E+99),IF(AND(AW7<>"",LOWER(AW7)<>"approved",LOWER(AW7)<>"n/a",ISNUMBER(AX7)),AX7,1E+99),IF(AND(AZ7<>"",LOWER(AZ7)<>"approved",LOWER(AZ7)<>"n/a",ISNUMBER(BA7)),BA7,1E+99)),_xlpm.sw,IF(AG7="","",IFERROR("SW"&MID(AG7,FIND("/W",AG7)+2,99),"SW "&AG7)),_xlpm.stage&IF(_xlpm.parts="","All development items approved/closed",_xlpm.parts)&IF(AND(_xlpm.parts<>"",_xlpm.deadline<1E+99),"; need approval by "&TEXT(_xlpm.deadline,"d-mmm-yy"),"")&IF(_xlpm.sw<>""," for "&_xlpm.sw,""))) -> READY
A8: =IFERROR(VLOOKUP(E8,'Customer '!$A$4:$D$23,3,FALSE),"") -> RH | B8: NPI | C8: BIEN | D8: Sue Bilstad | E8: RESTORATION HARDWARE_HS | F8: =IFERROR(VLOOKUP(E8,'Customer '!$A$4:$D$28,2,FALSE),"") -> RH | G8: GRAND HYATT BAHA MAR-PHASE 2 | H8: =IF(OR(DetailTracker[[#This Row],[PROJECT NAME (SHORT)]]="",DetailTracker[[#This Row],[CUSTOMER SHORTEN NAME]]=""),"",IF(ISNUMBER(DetailTracker[[#This Row],[BOQ DATE]]),YEAR(DetailTracker[[#This Row],[BOQ DATE]])&"-"&DetailTracker[[#This Row],[CUSTOMER SHORTEN NAME]]&"-"&DetailTracker[[#This Row],[PROJECT NAME (SHORT)]],IF(OR(DetailTracker[[#This Row],[SHIP MONTH FC]]="TBC",DetailTracker[[#This Row],[SHIP MONTH FC]]="Removed"),DetailTracker[[#This Row],[SHIP MONTH FC]]&"-"&DetailTracker[[#This Row],[CUSTOMER SHORTEN NAME]]&"-"&DetailTracker[[#This Row],[PROJECT NAME (SHORT)]],YEAR(TODAY())&"-"&DetailTracker[[#This Row],[CUSTOMER SHORTEN NAME]]&"-"&DetailTracker[[#This Row],[PROJECT NAME (SHORT)]]))) -> 2026-RH-GRAND HYATT BAHA MAR-PHASE 2 | I8: =IF(OR($H8="",$B8=""),0,--(COUNTIFS($H$3:$H8,$H8,$B$3:$B8,$B8)=1)) -> 1 | J8: FC | K8: NEW | L8: 1. Preliminary Design | P8: BS | Q8: Bahamas | R8: 0 | S8: 0 | V8: 27 | X8: 2936224.5 | Y8: 1000000 | Z8: 2027/M06 | AA8: =IF(Z8="","",IF(OR(Z8="TBC",Z8="Removed"),Z8,LEFT(Z8,4))) -> 2027 | AD8: 46549 | AE8: 46626 | AF8: =IF(AD8="","",IF(ISNUMBER(AD8),IF(AND(AD8>='2026 Calendar'!$C$4,AD8<='2026 Calendar'!$E$107),LOOKUP(AD8,'2026 Calendar'!$C$4:$C$107,'2026 Calendar'!$A$4:$A$107),YEAR(AD8-WEEKDAY(AD8,2)+4)&"/W"&TEXT(WEEKNUM(AD8,21),"00")),IF(IFERROR(ISNUMBER(SEARCH("/W",AD8)),FALSE),IF(IFERROR(ISNUMBER(SEARCH("-",AD8)),FALSE),LEFT(AD8,SEARCH("-",AD8)-1),AD8),AD8))) -> 2027/W24 | AG8: =IF(AE8="","",IF(ISNUMBER(AE8),IF(AND(AE8>='2026 Calendar'!$C$4,AE8<='2026 Calendar'!$E$107),LOOKUP(AE8,'2026 Calendar'!$C$4:$C$107,'2026 Calendar'!$A$4:$A$107),YEAR(AE8-WEEKDAY(AE8,2)+4)&"/W"&TEXT(WEEKNUM(AE8,21),"00")),IF(IFERROR(ISNUMBER(SEARCH("/W",AE8)),FALSE),IF(IFERROR(ISNUMBER(SEARCH("-",AE8)),FALSE),MID(AE8,SEARCH("-",AE8)+1,100),AE8),AE8))) -> 2027/W35 | AH8: Not Started | AK8: Not Started | AN8: Not Started | AQ8: Not Started | AT8: N/A | AW8: Not Started | AZ8: Not Started | BC8: =IF(J8="","",IF(OR(J8="OB",J8="NOR",J8="FC",J8="PIPELINE"),"Active","Complete")) -> Active | BD8: Yes | BE8: =IF(UPPER(TRIM(J8))="SHIPPED","READY",_xlfn.LET(_xlpm.stage,IF(B8="","",B8&": "),_xlpm.ip,_xlfn.TEXTJOIN(", ",TRUE,IF(LOWER(AH8)="in progress","Drawing",""),IF(LOWER(AK8)="in progress","Veneer/Wood",""),IF(LOWER(AN8)="in progress","Marble",""),IF(LOWER(AQ8)="in progress","Metal",""),IF(LOWER(AT8)="in progress","Mirror",""),IF(LOWER(AW8)="in progress","Electrical",""),IF(LOWER(AZ8)="in progress","Fabric","")),_xlpm.pa,_xlfn.TEXTJOIN(", ",TRUE,IF(LOWER(AH8)="pending approval","Drawing",""),IF(LOWER(AK8)="pending approval","Veneer/Wood",""),IF(LOWER(AN8)="pending approval","Marble",""),IF(LOWER(AQ8)="pending approval","Metal",""),IF(LOWER(AT8)="pending approval","Mirror",""),IF(LOWER(AW8)="pending approval","Electrical",""),IF(LOWER(AZ8)="pending approval","Fabric","")),_xlpm.ns,_xlfn.TEXTJOIN(", ",TRUE,IF(LOWER(AH8)="not started","Drawing",""),IF(LOWER(AK8)="not started","Veneer/Wood",""),IF(LOWER(AN8)="not started","Marble",""),IF(LOWER(AQ8)="not started","Metal",""),IF(LOWER(AT8)="not started","Mirror",""),IF(LOWER(AW8)="not started","Electrical",""),IF(LOWER(AZ8)="not started","Fabric","")),_xlpm.fab,IF(OR(LOWER(AZ8)="com",LOWER(AZ8)="com pending",LOWER(AZ8)="com received"),"Fabric is "&LOWER(AZ8),""),_xlpm.parts,_xlfn.TEXTJOIN("; ",TRUE,IF(_xlpm.ip<>"","In progress: "&_xlpm.ip,""),IF(_xlpm.pa<>"","Pending approval: "&_xlpm.pa,""),IF(_xlpm.ns<>"","Not started: "&_xlpm.ns,""),_xlpm.fab),_xlpm.deadline,MIN(IF(AND(AH8<>"",LOWER(AH8)<>"approved",LOWER(AH8)<>"n/a",ISNUMBER(AI8)),AI8,1E+99),IF(AND(AK8<>"",LOWER(AK8)<>"approved",LOWER(AK8)<>"n/a",ISNUMBER(AL8)),AL8,1E+99),IF(AND(AN8<>"",LOWER(AN8)<>"approved",LOWER(AN8)<>"n/a",ISNUMBER(AO8)),AO8,1E+99),IF(AND(AQ8<>"",LOWER(AQ8)<>"approved",LOWER(AQ8)<>"n/a",ISNUMBER(AR8)),AR8,1E+99),IF(AND(AT8<>"",LOWER(AT8)<>"approved",LOWER(AT8)<>"n/a",ISNUMBER(AU8)),AU8,1E+99),IF(AND(AW8<>"",LOWER(AW8)<>"approved",LOWER(AW8)<>"n/a",ISNUMBER(AX8)),AX8,1E+99),IF(AND(AZ8<>"",LOWER(AZ8)<>"approved",LOWER(AZ8)<>"n/a",ISNUMBER(BA8)),BA8,1E+99)),_xlpm.sw,IF(AG8="","",IFERROR("SW"&MID(AG8,FIND("/W",AG8)+2,99),"SW "&AG8)),_xlpm.stage&IF(_xlpm.parts="","All development items approved/closed",_xlpm.parts)&IF(AND(_xlpm.parts<>"",_xlpm.deadline<1E+99),"; need approval by "&TEXT(_xlpm.deadline,"d-mmm-yy"),"")&IF(_xlpm.sw<>""," for "&_xlpm.sw,""))) -> NPI: Not started: Drawing, Veneer/Wood, Marble, Metal, Electrical, Fabric for SW35
